Workbook
Name _1__Initials_of_Montran_Quality_Assurance_inspector: #REF!
Name _1__Initials_of_Montran_Quality_Assurance_inspector: #REF!
Name _1__Initials_of_Montran_Quality_Assurance_inspector: #REF!
Name _1__Initials_of_Montran_Quality_Assurance_inspector: #REF!
Name _1__Initials_of_Montran_Quality_Assurance_inspector: #REF!
Name _1__Initials_of_Montran_Quality_Assurance_inspector: #REF!
Name _1__Initials_of_Montran_Quality_Assurance_inspector: #REF!
Name _Toc519249740: 'Test Suite'!#REF!
Name _Toc519249746: 'Test Suite'!#REF!
Name ACmail: #REF!
Name ACmail: #REF!
Name ACphone: #REF!
Name ACphone: #REF!
Name AcS: #REF!
Name AcS: #REF!
Name AcSmail: #REF!
Name AcSmail: #REF!
Name AcSphone: #REF!
Name AcSphone: #REF!
Name AGmail: #REF!
Name AGmail: #REF!
Name AGphone: #REF!
Name AGphone: #REF!
Name AnGlmail: #REF!
Name AnGlmail: #REF!
Name AnGlphone: #REF!
Name AnGlphone: #REF!
Name APmail: #REF!
Name APmail: #REF!
Name APopmail: #REF!
Name APopmail: #REF!
Name APopphone: #REF!
Name APopphone: #REF!
Name APphone: #REF!
Name APphone: #REF!
Name ARmail: #REF!
Name ARmail: #REF!
Name ARphone: #REF!
Name ARphone: #REF!
Name ASmail: #REF!
Name ASmail: #REF!
Name ASphone: #REF!
Name ASphone: #REF!
Name Aspmail: #REF!
Name Aspmail: #REF!
Name AsPphone: #REF!
Name AsPphone: #REF!
Name BDmail: #REF!
Name BDmail: #REF!
Name BDphone: #REF!
Name BDphone: #REF!
Name BPmail: #REF!
Name BPmail: #REF!
Name BPphone: #REF!
Name BPphone: #REF!
Name BQmail: #REF!
Name BQmail: #REF!
Name BQphone: #REF!
Name BQphone: #REF!
Name CaTmail: #REF!

Sheet Audit Trail
B2: Document Control
B3: Title: | C3: QA UAT Scripts per Functionality
B4: Code: | C4: QUA_TPL_QA_UAT_Scripts_per_Functionality
B5: Project:
B6: Confidentiality: | C6: INTERNAL USE ONLY
B7: Integrity: | C7: HIGH
B8: Availability: | C8: MEDIUM
B9: Deliverable: | C9: NO
B10: Version: | C10: 3
B12: Document Ownership
B13: Nature of involvement | C13: Name | D13: Institution | E13: Role
B14: Owned by: | C14: Ciprian Tesa | D14: Montran | E14: Engineering Manager
B15: First Draft by: | C15: QA Team | D15: Montran | E15: QA
B16: Last Verified by: | C16: Ciprian Tesa | D16: Montran | E16: Engineering Manager
B17: Reviewed/QA by: | C17: Ciprian Tesa | D17: Montran | E17: Engineering Manager
B18: Approved by: | C18: Ciprian Tesa | D18: Montran | E18: Engineering Manager
B19: Distributed to: | C19: All Emplyees
B21: Document History
B22: Date | C22: Version & Status | D22: Changes
B23: 43623 | C23: 0.01 DRAFT | D23: initial draft
B24: 43672 | C24: 0.02 DRAFT | D24: formatted, changed names of columns, added execution metrics.
B25: 43676 | C25: 0.03 DRAFT | D25: added defect metrics
B26: 43683 | C26: 0.04 DRAFT | D26: template splitting per module/ per functionality, modified QA accepted steps to step status - Passed (P), Failed (F), Blocked (B), added blocked to metrics, added description sheet
B27: 43714 | C27: 0.05 DRAFT | D27: adjusted Conditional Formatting
B28: 43728 | C28: 1 APPROVED | D28: Approved Version
B29: 43768 | C29: 2 APPROVED | D29: Approved Version
B30: 43784 | C30: 2.01 | D30: metrics charts and date formatting
B31: 44064 | C31: 2.01 | D31: review, no update
B32: 44463 | C32: 2.01 | D32: review, no update
B33: 44830 | C33: 3.00 APPROVED | D33: Periodic review, approved.
B34: 45183 | C34: 3.00 APPROVED | D34: Periodic review, no changes, approved.

Sheet Description
B2: Test Suite Details | C2: Description
B3: Test Suite Name:
B4: Test Suite Type: | C4: [choose one: Abstract/ Executable]
B5: Other relevant details:

Sheet Execution Metrics
A1: TC Execution | B1: Total | C1: Passed | D1: Failed/ Blocked | E1: Not Run
A2: Total | B2: =SUM(B5:B25) -> 2 | C2: =SUM(C5:C25) -> 0 | D2: =SUM(D5:D25) -> 0 | E2: =SUM(E5:E25) -> 2
A4: TC Execution per Functionality | B4: Total | C4: Passed | D4: Failed/ Blocked | E4: Not Run
A5: 01. Instalación | B5: =COUNTIFS('Test Suite'!D:D,'Execution Metrics'!A5) -> 1 | C5: =COUNTIFS('Test Suite'!D:D,'Execution Metrics'!A5,'Test Suite'!R:R,"P") -> 0 | D5: =COUNTIFS('Test Suite'!D:D,'Execution Metrics'!A5,'Test Suite'!R:R,"F")+COUNTIFS('Test Suite'!D:D,'Execution Metrics'!A5,'Test Suite'!R:R,"B") -> 0 | E5: =COUNTIFS('Test Suite'!D:D,'Execution Metrics'!A5,'Test Suite'!R:R,"") -> 1
A6: 02. Configuración del Sistema | B6: =COUNTIFS('Test Suite'!D:D,'Execution Metrics'!A6) -> 0 | C6: =COUNTIFS('Test Suite'!D:D,'Execution Metrics'!A6,'Test Suite'!R:R,"P") -> 0 | D6: =COUNTIFS('Test Suite'!D:D,'Execution Metrics'!A6,'Test Suite'!R:R,"F")+COUNTIFS('Test Suite'!D:D,'Execution Metrics'!A6,'Test Suite'!R:R,"B") -> 0 | E6: =COUNTIFS('Test Suite'!D:D,'Execution Metrics'!A6,'Test Suite'!R:R,"") -> 0
A7: 03. Autenticación de Usuario y Control de Acceso | B7: =COUNTIFS('Test Suite'!D:D,'Execution Metrics'!A7) -> 0 | C7: =COUNTIFS('Test Suite'!D:D,'Execution Metrics'!A7,'Test Suite'!R:R,"P") -> 0 | D7: =COUNTIFS('Test Suite'!D:D,'Execution Metrics'!A7,'Test Suite'!R:R,"F")+COUNTIFS('Test Suite'!D:D,'Execution Metrics'!A7,'Test Suite'!R:R,"B") -> 0 | E7: =COUNTIFS('Test Suite'!D:D,'Execution Metrics'!A7,'Test Suite'!R:R,"") -> 0
A8: 04. Actores | B8: =COUNTIFS('Test Suite'!D:D,'Execution Metrics'!A8) -> 1 | C8: =COUNTIFS('Test Suite'!D:D,'Execution Metrics'!A8,'Test Suite'!R:R,"P") -> 0 | D8: =COUNTIFS('Test Suite'!D:D,'Execution Metrics'!A8,'Test Suite'!R:R,"F")+COUNTIFS('Test Suite'!D:D,'Execution Metrics'!A8,'Test Suite'!R:R,"B") -> 0 | E8: =COUNTIFS('Test Suite'!D:D,'Execution Metrics'!A8,'Test Suite'!R:R,"") -> 1
A9: 05. Instrumentos Financieros | B9: =COUNTIFS('Test Suite'!D:D,'Execution Metrics'!A9) -> 0 | C9: =COUNTIFS('Test Suite'!D:D,'Execution Metrics'!A9,'Test Suite'!R:R,"P") -> 0 | D9: =COUNTIFS('Test Suite'!D:D,'Execution Metrics'!A9,'Test Suite'!R:R,"F")+COUNTIFS('Test Suite'!D:D,'Execution Metrics'!A9,'Test Suite'!R:R,"B") -> 0 | E9: =COUNTIFS('Test Suite'!D:D,'Execution Metrics'!A9,'Test Suite'!R:R,"") -> 0
A10: 06. Cuentas | B10: =COUNTIFS('Test Suite'!D:D,'Execution Metrics'!A10) -> 0 | C10: =COUNTIFS('Test Suite'!D:D,'Execution Metrics'!A10,'Test Suite'!R:R,"P") -> 0 | D10: =COUNTIFS('Test Suite'!D:D,'Execution Metrics'!A10,'Test Suite'!R:R,"F")+COUNTIFS('Test Suite'!D:D,'Execution Metrics'!A10,'Test Suite'!R:R,"B") -> 0 | E10: =COUNTIFS('Test Suite'!D:D,'Execution Metrics'!A10,'Test Suite'!R:R,"") -> 0
A11: 07. Subasta | B11: =COUNTIFS('Test Suite'!D:D,'Execution Metrics'!A11) -> 0 | C11: =COUNTIFS('Test Suite'!D:D,'Execution Metrics'!A11,'Test Suite'!R:R,"P") -> 0 | D11: =COUNTIFS('Test Suite'!D:D,'Execution Metrics'!A11,'Test Suite'!R:R,"F")+COUNTIFS('Test Suite'!D:D,'Execution Metrics'!A11,'Test Suite'!R:R,"B") -> 0 | E11: =COUNTIFS('Test Suite'!D:D,'Execution Metrics'!A11,'Test Suite'!R:R,"") -> 0
A12: 08. Acciones Corporativas | B12: =COUNTIFS('Test Suite'!D:D,'Execution Metrics'!A12) -> 0 | C12: =COUNTIFS('Test Suite'!D:D,'Execution Metrics'!A12,'Test Suite'!R:R,"P") -> 0 | D12: =COUNTIFS('Test Suite'!D:D,'Execution Metrics'!A12,'Test Suite'!R:R,"F")+COUNTIFS('Test Suite'!D:D,'Execution Metrics'!A12,'Test Suite'!R:R,"B") -> 0 | E12: =COUNTIFS('Test Suite'!D:D,'Execution Metrics'!A12,'Test Suite'!R:R,"") -> 0
A13: 09. Liquidación | B13: =COUNTIFS('Test Suite'!D:D,'Execution Metrics'!A13) -> 0 | C13: =COUNTIFS('Test Suite'!D:D,'Execution Metrics'!A13,'Test Suite'!R:R,"P") -> 0 | D13: =COUNTIFS('Test Suite'!D:D,'Execution Metrics'!A13,'Test Suite'!R:R,"F")+COUNTIFS('Test Suite'!D:D,'Execution Metrics'!A13,'Test Suite'!R:R,"B") -> 0 | E13: =COUNTIFS('Test Suite'!D:D,'Execution Metrics'!A13,'Test Suite'!R:R,"") -> 0
A14: 10. Parametrización del sistema | B14: =COUNTIFS('Test Suite'!D:D,'Execution Metrics'!A14) -> 0 | C14: =COUNTIFS('Test Suite'!D:D,'Execution Metrics'!A14,'Test Suite'!R:R,"P") -> 0 | D14: =COUNTIFS('Test Suite'!D:D,'Execution Metrics'!A14,'Test Suite'!R:R,"F")+COUNTIFS('Test Suite'!D:D,'Execution Metrics'!A14,'Test Suite'!R:R,"B") -> 0 | E14: =COUNTIFS('Test Suite'!D:D,'Execution Metrics'!A14,'Test Suite'!R:R,"") -> 0
A15: 11. Operaciones y Transacciones de Valores | B15: =COUNTIFS('Test Suite'!D:D,'Execution Metrics'!A15) -> 0 | C15: =COUNTIFS('Test Suite'!D:D,'Execution Metrics'!A15,'Test Suite'!R:R,"P") -> 0 | D15: =COUNTIFS('Test Suite'!D:D,'Execution Metrics'!A15,'Test Suite'!R:R,"F")+COUNTIFS('Test Suite'!D:D,'Execution Metrics'!A15,'Test Suite'!R:R,"B") -> 0 | E15: =COUNTIFS('Test Suite'!D:D,'Execution Metrics'!A15,'Test Suite'!R:R,"") -> 0
A16: 12. Elegibilidad de Colaterales | B16: =COUNTIFS('Test Suite'!D:D,'Execution Metrics'!A16) -> 0 | C16: =COUNTIFS('Test Suite'!D:D,'Execution Metrics'!A16,'Test Suite'!R:R,"P") -> 0 | D16: =COUNTIFS('Test Suite'!D:D,'Execution Metrics'!A16,'Test Suite'!R:R,"F")+COUNTIFS('Test Suite'!D:D,'Execution Metrics'!A16,'Test Suite'!R:R,"B") -> 0 | E16: =COUNTIFS('Test Suite'!D:D,'Execution Metrics'!A16,'Test Suite'!R:R,"") -> 0
... A25: 21. Migración | B25: =COUNTIFS('Test Suite'!D:D,'Execution Metrics'!A25) -> 0 | C25: =COUNTIFS('Test Suite'!D:D,'Execution Metrics'!A25,'Test Suite'!R:R,"P") -> 0 | D25: =COUNTIFS('Test Suite'!D:D,'Execution Metrics'!A25,'Test Suite'!R:R,"F")+COUNTIFS('Test Suite'!D:D,'Execution Metrics'!A25,'Test Suite'!R:R,"B") -> 0 | E25: =COUNTIFS('Test Suite'!D:D,'Execution Metrics'!A25,'Test Suite'!R:R,"") -> 0

Sheet Defect Metrics 1
A1: Defect distribution by status | B1: Total | C1: Open | D1: Closed
A2: Total | B2: =SUM(B5:B18) -> 21 | C2: =SUM(C5:C18) -> 10 | D2: =SUM(D5:D18) -> 11
A4: Defect distribution per Functionality by status | B4: Total | C4: Open | D4: Closed
A5: 01. First functionality | B5: 2 | C5: 0 | D5: 2
A6: 02. Second functionality | B6: 7 | C6: 3 | D6: 4
A7: 03. --- | B7: 3 | C7: 1 | D7: 2
A8: 04. --- | B8: 2 | C8: 1 | D8: 1
A9: 05. --- | B9: 0 | C9: 0 | D9: 0
A10: 06. --- | B10: 3 | C10: 3 | D10: 0
A11: 07. --- | B11: 4 | C11: 2 | D11: 2
A12: 08. --- | B12: 0 | C12: 0 | D12: 0
A13: 09. --- | B13: 0 | C13: 0 | D13: 0
A14: 10. --- | B14: 0 | C14: 0 | D14: 0
A15: 11. --- | B15: 0 | C15: 0 | D15: 0
A16: 12. --- | B16: 0 | C16: 0 | D16: 0
... A18: 14. --- | B18: 0 | C18: 0 | D18: 0

Sheet Defect Metrics 2
A1: Defect distribution by severity | B1: Total | C1: High/ Blocking | D1: Medium | E1: Low
A2: Total | B2: =SUM(B5:B18) -> 21 | C2: =SUM(C5:C18) -> 1 | D2: =SUM(D5:D18) -> 18 | E2: =SUM(E5:E18) -> 2
A4: Defect distribution per Functionality by severity | B4: Total | C4: High/ Blocking | D4: Medium | E4: Low
A5: 01. First functionality | B5: 2 | C5: 0 | D5: 2 | E5: 0
A6: 02. Second functionality | B6: 7 | C6: 0 | D6: 5 | E6: 2
A7: 03. --- | B7: 3 | C7: 1 | D7: 2 | E7: 0
A8: 04. --- | B8: 2 | C8: 0 | D8: 2 | E8: 0
A9: 05. --- | B9: 0 | C9: 0 | D9: 0 | E9: 0
A10: 06. --- | B10: 3 | C10: 0 | D10: 3 | E10: 0
A11: 07. --- | B11: 4 | C11: 0 | D11: 4 | E11: 0
A12: 08. --- | B12: 0 | C12: 0 | D12: 0 | E12: 0
A13: 09. --- | B13: 0 | C13: 0 | D13: 0 | E13: 0
A14: 10. --- | B14: 0 | C14: 0 | D14: 0 | E14: 0
A15: 11. --- | B15: 0 | C15: 0 | D15: 0 | E15: 0
A16: 12. --- | B16: 0 | C16: 0 | D16: 0 | E16: 0
... A18: 14. --- | B18: 0 | C18: 0 | D18: 0 | E18: 0

Sheet Test Suite
D1: TEST CASES: | G1: {=SUM(1/COUNTIF(C2:C46,C2:C46))-3} -> 9 | K1: =CONCATENATE("PASSED TEST STEPS - QA: ",ROUND((COUNTIF(A3:A46,2)/(COUNTA(D3:D46)))*100,0),"% ","(",COUNTIF(A3:A46,2),"/",COUNTA(D3:D46),")"," - UAT: ",ROUND((COUNTIF(B3:B46,2)/(COUNTA(D3:D46)))*100,0),"% ","(",COUNTIF(B3:B46,2),"/",COUNTA(D3:D46),")") -> PASSED TEST STEPS - QA: 0% (0/10) - UAT: 0% (0/10) | P1: QA | Z1: UAT
A2: QA | B2: UAT | C2: 0 | D2: Functionality Name | E2: Section Reference/Feature | F2: Test Scenario | G2: User Type | H2: TC No | I2: Step no | J2: Syntax | K2: Test Case Input Specifications/ Test steps | L2: Test Case Output Specifications/ Expected results | M2: Data | N2: Dependency | O2: Suite Tag | P2: Release | Q2: Execution Date (yyyy-mm-dd) | R2: Status (P/ F/ B) | S2: Retest Count | T2: Test Case Observations | U2: Priority | V2: Ticket Number RT | W2: Ticket Number JIRA | X2: Automated Test Case | Y2: Standard Test Case (Core) | Z2: Scheduled End Date (yyyy-mm-dd) | AA2: Actual End Date (yyyy-mm-dd) | AB2: Scheduled Acceptance Date (yyyy-mm-dd) | AC2: Actual Acceptance Date (yyyy-mm-dd) | AD2: Accepted (Y/N) | AE2: Comments / Observations
A3: =IF(R3="P", 2,IF(R3="F",1,IF(R3="B",1,0))) -> 0 | B3: =IF(AD3="Y", 2,IF(AD3="N",1,0)) -> 0 | C3: =IF(H3=H2,C2,C2+1) -> 1 | D3: 01. Instalación | E3: 1.1. Reporte de instalación para el sistema | F3: Instalar el sistema en los ambientes definidos. | G3: Administrador | H3: TC000 | I3: 1 | J3: Given | K3: Prerequisites: | X3: No | Y3: Yes
C4: =IF(H4=H3,C3,C3+1) -> 1 | E4: 1.1. Reporte de instalación para el sistema | F4: Instalar el sistema en los ambientes definidos. | H4: TC000 | I4: 2 | J4: When | K4: Second step input.
C5: =IF(H5=H4,C4,C4+1) -> 1 | E5: 1.1. Reporte de instalación para el sistema | F5: Instalar el sistema en los ambientes definidos. | H5: TC000 | I5: 3 | J5: And | K5: 3
C6: =IF(H6=H5,C5,C5+1) -> 1 | E6: 1.1. Reporte de instalación para el sistema | F6: Instalar el sistema en los ambientes definidos. | H6: TC000 | I6: 4 | J6: Then | K6: 4 | L6: Test case output.
A7: =IF(R7="P", 2,IF(R7="F",1,IF(R7="B",1,0))) -> 0 | B7: =IF(AD7="Y", 2,IF(AD7="N",1,0)) -> 0 | C7: =IF(H7=H6,C6,C6+1) -> 2 | D7: 02. Generalidades | E7: 2.1. Cabecera superior | F7: Redireccionar hacia la página principal | G7: Administrador, No Administrador | H7: TC001 | I7: 1 | J7: Given | K7: 6
C8: =IF(H8=H7,C7,C7+1) -> 2 | E8: 2.1. Cabecera superior | F8: Redireccionar hacia la página principal | H8: TC001 | I8: 2 | J8: When | K8: q
C9: =IF(H9=H8,C8,C8+1) -> 2 | E9: 2.1. Cabecera superior | F9: Redireccionar hacia la página principal | H9: TC001 | I9: 3 | J9: And | K9: daf
C10: =IF(H10=H9,C9,C9+1) -> 2 | E10: 2.1. Cabecera superior | F10: Redireccionar hacia la página principal | H10: TC001 | I10: 4 | J10: Then | K10: adg
A11: =IF(R11="P", 2,IF(R11="F",1,IF(R11="B",1,0))) -> 0 | B11: =IF(AD11="Y", 2,IF(AD11="N",1,0)) -> 0 | C11: =IF(H11=H10,C10,C10+1) -> 3 | D11: 02. Generalidades | E11: 2.1. Cabecera superior | F11: Redireccionar hacia las Nuevas Alertas | G11: Administrador, No Administrador | H11: TC002 | I11: 1 | J11: Given | K11: wr
C12: =IF(H12=H11,C11,C11+1) -> 3 | E12: 2.1. Cabecera superior | F12: Redireccionar hacia las Nuevas Alertas | H12: TC002 | I12: 2 | J12: When | K12: df
C13: =IF(H13=H12,C12,C12+1) -> 3 | E13: 2.1. Cabecera superior | F13: Redireccionar hacia las Nuevas Alertas | H13: TC002 | I13: 3 | J13: And | K13: dfaf
C14: =IF(H14=H13,C13,C13+1) -> 3 | E14: 2.1. Cabecera superior | F14: Redireccionar hacia las Nuevas Alertas | H14: TC002 | I14: 4 | J14: Then | K14: afda
A15: =IF(R15="P", 2,IF(R15="F",1,IF(R15="B",1,0))) -> 0 | B15: =IF(AD15="Y", 2,IF(AD15="N",1,0)) -> 0 | C15: =IF(H15=H14,C14,C14+1) -> 4 | D15: 02. Generalidades | E15: 2.1. Cabecera superior | F15: Cerrar sesión | G15: Administrador, No Administrador | H15: TC003 | I15: 1 | J15: Given | K15: afda
C16: =IF(H16=H15,C15,C15+1) -> 4 | E16: 2.1. Cabecera superior | F16: Cerrar sesión | H16: TC003 | I16: 2 | J16: When | K16: afda
C17: =IF(H17=H16,C16,C16+1) -> 4 | E17: 2.1. Cabecera superior | F17: Cerrar sesión | H17: TC003 | I17: 3 | J17: And | K17: fad
C18: =IF(H18=H17,C17,C17+1) -> 4 | E18: 2.1. Cabecera superior | F18: Cerrar sesión | H18: TC003 | I18: 4 | J18: Then | K18: fad
A19: =IF(R19="P", 2,IF(R19="F",1,IF(R19="B",1,0))) -> 0 | B19: =IF(AD19="Y", 2,IF(AD19="N",1,0)) -> 0 | C19: =IF(H19=H18,C18,C18+1) -> 5 | D19: 02. Generalidades | E19: 2.2. Página principal de Inicio | F19: Visualizar el Horario Diario | G19: Administrador, No Administrador | H19: TC001 | I19: 1 | J19: Given | K19: fad
C20: =IF(H20=H19,C19,C19+1) -> 5 | E20: 2.2. Página principal de Inicio | F20: Visualizar el Horario Diario | H20: TC001 | I20: 2 | J20: When | K20: adf
C21: =IF(H21=H20,C20,C20+1) -> 5 | E21: 2.2. Página principal de Inicio | F21: Visualizar el Horario Diario | H21: TC001 | I21: 3 | J21: And | K21: adf
C22: =IF(H22=H21,C21,C21+1) -> 5 | E22: 2.2. Página principal de Inicio | F22: Visualizar el Horario Diario | H22: TC001 | I22: 4 | J22: Then | K22: ad | M22: Usuario_DATA
A23: =IF(R23="P", 2,IF(R23="F",1,IF(R23="B",1,0))) -> 0 | B23: =IF(AD23="Y", 2,IF(AD23="N",1,0)) -> 0 | C23: =IF(H23=H22,C22,C22+1) -> 6 | D23: 02. Generalidades | E23: 2.2. Página principal de Inicio | F23: Visualizar entidades en Espera de Aprobación | G23: Administrador, No Administrador | H23: TC002 | I23: 1 | J23: Given | K23: fad
C24: =IF(H24=H23,C23,C23+1) -> 6 | E24: 2.2. Página principal de Inicio | F24: Visualizar entidades en Espera de Aprobación | H24: TC002 | I24: 2 | J24: When | K24: fad
C25: =IF(H25=H24,C24,C24+1) -> 6 | E25: 2.2. Página principal de Inicio | F25: Visualizar entidades en Espera de Aprobación | H25: TC002 | I25: 3 | J25: And | K25: a
C26: =IF(H26=H25,C25,C25+1) -> 6 | E26: 2.2. Página principal de Inicio | F26: Visualizar entidades en Espera de Aprobación | H26: TC002 | I26: 4 | J26: Then | K26: fad
A27: =IF(R27="P", 2,IF(R27="F",1,IF(R27="B",1,0))) -> 0 | B27: =IF(AD27="Y", 2,IF(AD27="N",1,0)) -> 0 | C27: =IF(H27=H26,C26,C26+1) -> 7 | D27: 02. Generalidades | E27: 2.3. Menú | F27: Acceder a las opciones de menú y sub-menús | G27: Administrador, No Administrador | H27: TC001 | I27: 1 | J27: Given | K27: gr
C28: =IF(H28=H27,C27,C27+1) -> 7 | E28: 2.3. Menú | F28: Acceder a las opciones de menú y sub-menús | H28: TC001 | I28: 2 | J28: When | K28: ga
C29: =IF(H29=H28,C28,C28+1) -> 7 | E29: 2.3. Menú | F29: Acceder a las opciones de menú y sub-menús | H29: TC001 | I29: 3 | J29: And | K29: fad
C30: =IF(H30=H29,C29,C29+1) -> 7 | E30: 2.3. Menú | F30: Acceder a las opciones de menú y sub-menús | H30: TC001 | I30: 4 | J30: Then | K30: eg
A31: =IF(R31="P", 2,IF(R31="F",1,IF(R31="B",1,0))) -> 0 | B31: =IF(AD31="Y", 2,IF(AD31="N",1,0)) -> 0 | C31: =IF(H31=H30,C30,C30+1) -> 8 | D31: 02. Generalidades | E31: 2.3. Menú | F31: Buscar menús y/o sub-menús | G31: Administrador, No Administrador | H31: TC002 | I31: 1 | J31: Given | K31: a
C32: =IF(H32=H31,C31,C31+1) -> 8 | E32: 2.3. Menú | F32: Buscar menús y/o sub-menús | H32: TC002 | I32: 2 | J32: When | K32: sd
C33: =IF(H33=H32,C32,C32+1) -> 8 | E33: 2.3. Menú | F33: Buscar menús y/o sub-menús | H33: TC002 | I33: 3 | J33: And | K33: a
C34: =IF(H34=H33,C33,C33+1) -> 8 | E34: 2.3. Menú | F34: Buscar menús y/o sub-menús | H34: TC002 | I34: 4 | J34: Then | K34: g
A35: =IF(R35="P", 2,IF(R35="F",1,IF(R35="B",1,0))) -> 0 | B35: =IF(AD35="Y", 2,IF(AD35="N",1,0)) -> 0 | C35: =IF(H35=H34,C34,C34+1) -> 9 | D35: 02. Generalidades | E35: 2.4. Listar | F35: Verificar visualización de la sección Buscar | G35: Administrador, No Administrador | I35: 1 | J35: Given | K35: s
C36: =IF(H36=H35,C35,C35+1) -> 9 | E36: 2.4. Listar | F36: Verificar visualización de la sección Buscar | I36: 2 | J36: When | K36: ge
C37: =IF(H37=H36,C36,C36+1) -> 9 | E37: 2.4. Listar | F37: Verificar visualización de la sección Buscar | I37: 3 | J37: And | K37: ca
C38: =IF(H38=H37,C37,C37+1) -> 9 | E38: 2.4. Listar | F38: Verificar visualización de la sección Buscar | I38: 4 | J38: Then | K38: eer
A39: =IF(R39="P", 2,IF(R39="F",1,IF(R39="B",1,0))) -> 0 | B39: =IF(AD39="Y", 2,IF(AD39="N",1,0)) -> 0 | C39: =IF(H39=H38,C38,C38+1) -> 10 | D39: 04. Actores | E39: 4.1. Administración de Instituciones | F39: Crear una nueva institución - Ingreso correcto de todos los campos del formulario | G39: Administrador | H39: TC073 | I39: 1 | J39: Given | K39: Access the CSD system | N39: =IF(I39=1, D39 & " / " & E39 & " / " & TEXT(H39,"000") & " _ " & F39, N39) -> 04. Actores / 4.1. Administración de Instituciones / TC073 _ Crear una nueva institución - Ingreso correcto de todos los campos del formulario
C40: =IF(H40=H39,C39,C39+1) -> 10 | E40: 4.1. Administración de Instituciones | F40: Crear una nueva institución - Ingreso correcto de todos los campos del formulario | G40: Administrador | H40: TC073 | I40: 2 | J40: And | K40: Navigate through the menu: Stakeholders / Institutions / Create | N40: =IF(I40=1, D40 & " / " & E40 & " / " & TEXT(H40,"000") & " _ " & F40, N40) -> 04. Actores / 4.1. Administración de Instituciones / TC073 _ Crear una nueva institución - Ingreso correcto de todos los campos del formulario
...

Sheet JIRA_QP
A1: Issue Key | B1: Test case name | C1: Description | D1: Test Step | E1: Test Result | F1: Test Data
B2: =_xlfn.CONCAT('Test Suite'!E3," / ",'Test Suite'!H3,"_",'Test Suite'!F3) -> 1.1. Reporte de instalación para el sistema / TC000_Instalar el sistema en los ambientes definidos. | D2: =_xlfn.CONCAT('Test Suite'!J3," ",'Test Suite'!K3) -> Given Prerequisites: | E2: =IF('Test Suite'!L3="","",'Test Suite'!L3) | F2: =IF('Test Suite'!#REF!="","",'Test Suite'!#REF!) -> #REF!
B3: =_xlfn.CONCAT('Test Suite'!E4," / ",'Test Suite'!H4,"_",'Test Suite'!F4) -> 1.1. Reporte de instalación para el sistema / TC000_Instalar el sistema en los ambientes definidos. | D3: =_xlfn.CONCAT('Test Suite'!J4," ",'Test Suite'!K4) -> When Second step input. | E3: =IF('Test Suite'!L4="","",'Test Suite'!L4) | F3: =IF('Test Suite'!#REF!="","",'Test Suite'!#REF!) -> #REF!
B4: =_xlfn.CONCAT('Test Suite'!E5," / ",'Test Suite'!H5,"_",'Test Suite'!F5) -> 1.1. Reporte de instalación para el sistema / TC000_Instalar el sistema en los ambientes definidos. | D4: =_xlfn.CONCAT('Test Suite'!J5," ",'Test Suite'!K5) -> And 3 | E4: =IF('Test Suite'!L5="","",'Test Suite'!L5) | F4: =IF('Test Suite'!#REF!="","",'Test Suite'!#REF!) -> #REF!
B5: =_xlfn.CONCAT('Test Suite'!E6," / ",'Test Suite'!H6,"_",'Test Suite'!F6) -> 1.1. Reporte de instalación para el sistema / TC000_Instalar el sistema en los ambientes definidos. | D5: =_xlfn.CONCAT('Test Suite'!J6," ",'Test Suite'!K6) -> Then 4 | E5: =IF('Test Suite'!L6="","",'Test Suite'!L6) -> Test case output. | F5: =IF('Test Suite'!#REF!="","",'Test Suite'!#REF!) -> #REF!
B6: =_xlfn.CONCAT('Test Suite'!E7," / ",'Test Suite'!H7,"_",'Test Suite'!F7) -> 2.1. Cabecera superior / TC001_Redireccionar hacia la página principal | D6: =_xlfn.CONCAT('Test Suite'!J7," ",'Test Suite'!K7) -> Given 6 | E6: =IF('Test Suite'!L7="","",'Test Suite'!L7) | F6: =IF('Test Suite'!#REF!="","",'Test Suite'!#REF!) -> #REF!
B7: =_xlfn.CONCAT('Test Suite'!E8," / ",'Test Suite'!H8,"_",'Test Suite'!F8) -> 2.1. Cabecera superior / TC001_Redireccionar hacia la página principal | D7: =_xlfn.CONCAT('Test Suite'!J8," ",'Test Suite'!K8) -> When q | E7: =IF('Test Suite'!L8="","",'Test Suite'!L8) | F7: =IF('Test Suite'!#REF!="","",'Test Suite'!#REF!) -> #REF!
B8: =_xlfn.CONCAT('Test Suite'!E9," / ",'Test Suite'!H9,"_",'Test Suite'!F9) -> 2.1. Cabecera superior / TC001_Redireccionar hacia la página principal | D8: =_xlfn.CONCAT('Test Suite'!J9," ",'Test Suite'!K9) -> And daf | E8: =IF('Test Suite'!L9="","",'Test Suite'!L9) | F8: =IF('Test Suite'!#REF!="","",'Test Suite'!#REF!) -> #REF!
B9: =_xlfn.CONCAT('Test Suite'!E10," / ",'Test Suite'!H10,"_",'Test Suite'!F10) -> 2.1. Cabecera superior / TC001_Redireccionar hacia la página principal | D9: =_xlfn.CONCAT('Test Suite'!J10," ",'Test Suite'!K10) -> Then adg | E9: =IF('Test Suite'!L10="","",'Test Suite'!L10) | F9: =IF('Test Suite'!#REF!="","",'Test Suite'!#REF!) -> #REF!
B10: =_xlfn.CONCAT('Test Suite'!E11," / ",'Test Suite'!H11,"_",'Test Suite'!F11) -> 2.1. Cabecera superior / TC002_Redireccionar hacia las Nuevas Alertas | D10: =_xlfn.CONCAT('Test Suite'!J11," ",'Test Suite'!K11) -> Given wr | E10: =IF('Test Suite'!L11="","",'Test Suite'!L11) | F10: =IF('Test Suite'!#REF!="","",'Test Suite'!#REF!) -> #REF!
B11: =_xlfn.CONCAT('Test Suite'!E12," / ",'Test Suite'!H12,"_",'Test Suite'!F12) -> 2.1. Cabecera superior / TC002_Redireccionar hacia las Nuevas Alertas | D11: =_xlfn.CONCAT('Test Suite'!J12," ",'Test Suite'!K12) -> When df | E11: =IF('Test Suite'!L12="","",'Test Suite'!L12) | F11: =IF('Test Suite'!#REF!="","",'Test Suite'!#REF!) -> #REF!
B12: =_xlfn.CONCAT('Test Suite'!E13," / ",'Test Suite'!H13,"_",'Test Suite'!F13) -> 2.1. Cabecera superior / TC002_Redireccionar hacia las Nuevas Alertas | D12: =_xlfn.CONCAT('Test Suite'!J13," ",'Test Suite'!K13) -> And dfaf | E12: =IF('Test Suite'!L13="","",'Test Suite'!L13) | F12: =IF('Test Suite'!#REF!="","",'Test Suite'!#REF!) -> #REF!
B13: =_xlfn.CONCAT('Test Suite'!E14," / ",'Test Suite'!H14,"_",'Test Suite'!F14) -> 2.1. Cabecera superior / TC002_Redireccionar hacia las Nuevas Alertas | D13: =_xlfn.CONCAT('Test Suite'!J14," ",'Test Suite'!K14) -> Then afda | E13: =IF('Test Suite'!L14="","",'Test Suite'!L14) | F13: =IF('Test Suite'!#REF!="","",'Test Suite'!#REF!) -> #REF!
... B37: =_xlfn.CONCAT('Test Suite'!E38," / ",'Test Suite'!H38,"_",'Test Suite'!F38) -> 2.4. Listar / _Verificar visualización de la sección Buscar | D37: =_xlfn.CONCAT('Test Suite'!J38," ",'Test Suite'!K38) -> Then eer | E37: =IF('Test Suite'!L38="","",'Test Suite'!L38) | F37: =IF('Test Suite'!#REF!="","",'Test Suite'!#REF!) -> #REF!
B38: =_xlfn.CONCAT('Test Suite'!#REF!," / ",'Test Suite'!#REF!,"_",'Test Suite'!#REF!) -> #REF! | D38: =_xlfn.CONCAT('Test Suite'!#REF!," ",'Test Suite'!#REF!) -> #REF! | E38: =IF('Test Suite'!#REF!="","",'Test Suite'!#REF!) -> #REF! | F38: =IF('Test Suite'!#REF!="","",'Test Suite'!#REF!) -> #REF!
B39: =_xlfn.CONCAT('Test Suite'!#REF!," / ",'Test Suite'!#REF!,"_",'Test Suite'!#REF!) -> #REF! | D39: =_xlfn.CONCAT('Test Suite'!#REF!," ",'Test Suite'!#REF!) -> #REF! | E39: =IF('Test Suite'!#REF!="","",'Test Suite'!#REF!) -> #REF! | F39: =IF('Test Suite'!#REF!="","",'Test Suite'!#REF!) -> #REF!
B40: =_xlfn.CONCAT('Test Suite'!#REF!," / ",'Test Suite'!#REF!,"_",'Test Suite'!#REF!) -> #REF! | D40: =_xlfn.CONCAT('Test Suite'!#REF!," ",'Test Suite'!#REF!) -> #REF! | E40: =IF('Test Suite'!#REF!="","",'Test Suite'!#REF!) -> #REF! | F40: =IF('Test Suite'!#REF!="","",'Test Suite'!#REF!) -> #REF!
B41: =_xlfn.CONCAT('Test Suite'!#REF!," / ",'Test Suite'!#REF!,"_",'Test Suite'!#REF!) -> #REF! | D41: =_xlfn.CONCAT('Test Suite'!#REF!," ",'Test Suite'!#REF!) -> #REF! | E41: =IF('Test Suite'!#REF!="","",'Test Suite'!#REF!) -> #REF! | F41: =IF('Test Suite'!#REF!="","",'Test Suite'!#REF!) -> #REF!
B42: =_xlfn.CONCAT('Test Suite'!#REF!," / ",'Test Suite'!#REF!,"_",'Test Suite'!#REF!) -> #REF! | D42: =_xlfn.CONCAT('Test Suite'!#REF!," ",'Test Suite'!#REF!) -> #REF! | E42: =IF('Test Suite'!#REF!="","",'Test Suite'!#REF!) -> #REF! | F42: =IF('Test Suite'!#REF!="","",'Test Suite'!#REF!) -> #REF!
B43: =_xlfn.CONCAT('Test Suite'!#REF!," / ",'Test Suite'!#REF!,"_",'Test Suite'!#REF!) -> #REF! | D43: =_xlfn.CONCAT('Test Suite'!#REF!," ",'Test Suite'!#REF!) -> #REF! | E43: =IF('Test Suite'!#REF!="","",'Test Suite'!#REF!) -> #REF! | F43: =IF('Test Suite'!#REF!="","",'Test Suite'!#REF!) -> #REF!
B44: =_xlfn.CONCAT('Test Suite'!#REF!," / ",'Test Suite'!#REF!,"_",'Test Suite'!#REF!) -> #REF! | D44: =_xlfn.CONCAT('Test Suite'!#REF!," ",'Test Suite'!#REF!) -> #REF! | E44: =IF('Test Suite'!#REF!="","",'Test Suite'!#REF!) -> #REF! | F44: =IF('Test Suite'!#REF!="","",'Test Suite'!#REF!) -> #REF!
B45: =_xlfn.CONCAT('Test Suite'!#REF!," / ",'Test Suite'!#REF!,"_",'Test Suite'!#REF!) -> #REF! | D45: =_xlfn.CONCAT('Test Suite'!#REF!," ",'Test Suite'!#REF!) -> #REF! | E45: =IF('Test Suite'!#REF!="","",'Test Suite'!#REF!) -> #REF! | F45: =IF('Test Suite'!#REF!="","",'Test Suite'!#REF!) -> #REF!
B46: =_xlfn.CONCAT('Test Suite'!#REF!," / ",'Test Suite'!#REF!,"_",'Test Suite'!#REF!) -> #REF! | D46: =_xlfn.CONCAT('Test Suite'!#REF!," ",'Test Suite'!#REF!) -> #REF! | E46: =IF('Test Suite'!#REF!="","",'Test Suite'!#REF!) -> #REF! | F46: =IF('Test Suite'!#REF!="","",'Test Suite'!#REF!) -> #REF!
B47: =_xlfn.CONCAT('Test Suite'!#REF!," / ",'Test Suite'!#REF!,"_",'Test Suite'!#REF!) -> #REF! | D47: =_xlfn.CONCAT('Test Suite'!#REF!," ",'Test Suite'!#REF!) -> #REF! | E47: =IF('Test Suite'!#REF!="","",'Test Suite'!#REF!) -> #REF! | F47: =IF('Test Suite'!#REF!="","",'Test Suite'!#REF!) -> #REF!
B48: =_xlfn.CONCAT('Test Suite'!#REF!," / ",'Test Suite'!#REF!,"_",'Test Suite'!#REF!) -> #REF! | D48: =_xlfn.CONCAT('Test Suite'!#REF!," ",'Test Suite'!#REF!) -> #REF! | E48: =IF('Test Suite'!#REF!="","",'Test Suite'!#REF!) -> #REF! | F48: =IF('Test Suite'!#REF!="","",'Test Suite'!#REF!) -> #REF!
B49: =_xlfn.CONCAT('Test Suite'!#REF!," / ",'Test Suite'!#REF!,"_",'Test Suite'!#REF!) -> #REF! | D49: =_xlfn.CONCAT('Test Suite'!#REF!," ",'Test Suite'!#REF!) -> #REF! | E49: =IF('Test Suite'!#REF!="","",'Test Suite'!#REF!) -> #REF! | F49: =IF('Test Suite'!#REF!="","",'Test Suite'!#REF!) -> #REF!
... B122: =_xlfn.CONCAT('Test Suite'!#REF!," / ",'Test Suite'!#REF!,"_",'Test Suite'!#REF!) -> #REF! | D122: =_xlfn.CONCAT('Test Suite'!#REF!," ",'Test Suite'!#REF!) -> #REF! | E122: =IF('Test Suite'!#REF!="","",'Test Suite'!#REF!) -> #REF! | F122: =IF('Test Suite'!#REF!="","",'Test Suite'!#REF!) -> #REF!

Sheet Perfil_DATA
A1: Test Case No | B1: Field 1 | C1: Field 2 | D1: Field 3 | E1: Field 4 | F1: Field 5
A2: TC003 🔗 | B2: value 123 | C2: value ABC | D2: date DD/MM/YYYY | E2: X | F2: X
A3: TC004 🔗 | B3: value 123 | C3: null | D3: date DD/MM/YYYY | E3: X | F3: X

Sheet Usuario_DATA
A1: Test Case No | B1: Name | C1: Pass | D1: fecha | E1: Cuidad | F1: Pais
A2: TC001 | B2: value 123 | C2: value ABC | D2: date DD/MM/YYYY | E2: X | F2: X

Sheet PolíticaContraseña_DATA
A1: Test Case No | B1: Field 1 | C1: Field 2 | D1: Field 3 | E1: Field 4 | F1: Field 5
A2: TC006 🔗 | B2: value 123 | C2: value ABC | D2: date DD/MM/YYYY | E2: X | F2: X

Sheet PoderLegalUsuario_DATA
A1: Test Case No | B1: Field 1 | C1: Field 2 | D1: Field 3 | E1: Field 4 | F1: Field 5
A2: TC006 🔗 | B2: value 123 | C2: value ABC | D2: date DD/MM/YYYY | E2: X | F2: X

Sheet PoderLegalAccesoUsuario_DATA
A1: Test Case No | B1: Field 1 | C1: Field 2 | D1: Field 3 | E1: Field 4 | F1: Field 5
A2: TC006 🔗 | B2: value 123 | C2: value ABC | D2: date DD/MM/YYYY | E2: X | F2: X

Sheet PoderLegalCuentas_DATA
A1: Test Case No | B1: Field 1 | C1: Field 2 | D1: Field 3 | E1: Field 4 | F1: Field 5
A2: TC006 🔗 | B2: value 123 | C2: value ABC | D2: date DD/MM/YYYY | E2: X | F2: X

Sheet PoderLegalAccesoCuentas_DATA
A1: Test Case No | B1: Field 1 | C1: Field 2 | D1: Field 3 | E1: Field 4 | F1: Field 5
A2: TC006 🔗 | B2: value 123 | C2: value ABC | D2: date DD/MM/YYYY | E2: X | F2: X

Sheet Institucion_DATA
A1: Test Case No | B1: Field 1 | C1: Field 2 | D1: Field 3 | E1: Field 4 | F1: Field 5
A2: TC073 | B2: value 123 | C2: value ABC | D2: date DD/MM/YYYY | E2: X | F2: X

Sheet Participante_DATA
A1: Test Case No | B1: Field 1 | C1: Field 2 | D1: Field 3 | E1: Field 4 | F1: Field 5
A2: TC007 🔗 | B2: value 123 | C2: value ABC | D2: date DD/MM/YYYY | E2: X | F2: X

Sheet Emisor_DATA
A1: Test Case No | B1: Field 1 | C1: Field 2 | D1: Field 3 | E1: Field 4 | F1: Field 5
A2: TC007 🔗 | B2: value 123 | C2: value ABC | D2: date DD/MM/YYYY | E2: X | F2: X

Sheet BancoLiquidador_DATA
A1: Test Case No | B1: Field 1 | C1: Field 2 | D1: Field 3 | E1: Field 4 | F1: Field 5
A2: TC007 🔗 | B2: value 123 | C2: value ABC | D2: date DD/MM/YYYY | E2: X | F2: X

Sheet TechoComercial_DATA
A1: Test Case No | B1: Field 1 | C1: Field 2 | D1: Field 3 | E1: Field 4 | F1: Field 5
A2: TC007 🔗 | B2: value 123 | C2: value ABC | D2: date DD/MM/YYYY | E2: X | F2: X

Sheet Regulador_DATA
A1: Test Case No | B1: Field 1 | C1: Field 2 | D1: Field 3 | E1: Field 4 | F1: Field 5
A2: TC007 🔗 | B2: value 123 | C2: value ABC | D2: date DD/MM/YYYY | E2: X | F2: X

Sheet Cliente_DATA
A1: Test Case No | B1: Field 1 | C1: Field 2 | D1: Field 3 | E1: Field 4 | F1: Field 5
A2: TC007 🔗 | B2: value 123 | C2: value ABC | D2: date DD/MM/YYYY | E2: X | F2: X

Sheet ProgramaEmisión_DATA
A1: Test Case No | B1: Field 1 | C1: Field 2 | D1: Field 3 | E1: Field 4 | F1: Field 5
A2: } | B2: value 123 | C2: value ABC | D2: date DD/MM/YYYY | E2: X | F2: X

Sheet CategoríaInstrumento_DATA
A1: Test Case No | B1: Field 1 | C1: Field 2 | D1: Field 3 | E1: Field 4 | F1: Field 5
A2: } | B2: value 123 | C2: value ABC | D2: date DD/MM/YYYY | E2: X | F2: X

Sheet TítuloValor_DATA
A1: Test Case No | B1: Field 1 | C1: Field 2 | D1: Field 3 | E1: Field 4 | F1: Field 5
A2: } | B2: value 123 | C2: value ABC | D2: date DD/MM/YYYY | E2: X | F2: X

Sheet ÍndiceVinculado_DATA
A1: Test Case No | B1: Field 1 | C1: Field 2 | D1: Field 3 | E1: Field 4 | F1: Field 5
A2: } | B2: value 123 | C2: value ABC | D2: date DD/MM/YYYY | E2: X | F2: X

Sheet DatoÍndiceVinculado_DATA
A1: Test Case No | B1: Field 1 | C1: Field 2 | D1: Field 3 | E1: Field 4 | F1: Field 5
A2: } | B2: value 123 | C2: value ABC | D2: date DD/MM/YYYY | E2: X | F2: X

Sheet CurvaRendimiento_DATA
A1: Test Case No | B1: Field 1 | C1: Field 2 | D1: Field 3 | E1: Field 4 | F1: Field 5
A2: } | B2: value 123 | C2: value ABC | D2: date DD/MM/YYYY | E2: X | F2: X

Sheet ImportarCurvaRendimiento_DATA
A1: Test Case No | B1: Field 1 | C1: Field 2 | D1: Field 3 | E1: Field 4 | F1: Field 5
A2: } | B2: value 123 | C2: value ABC | D2: date DD/MM/YYYY | E2: X | F2: X

Sheet CuentaValor_DATA
A1: Test Case No | B1: Field 1 | C1: Field 2 | D1: Field 3 | E1: Field 4 | F1: Field 5
A2: } | B2: value 123 | C2: value ABC | D2: date DD/MM/YYYY | E2: X | F2: X

Sheet CuentaEfectivo_DATA
A1: Test Case No | B1: Field 1 | C1: Field 2 | D1: Field 3 | E1: Field 4 | F1: Field 5
A2: } | B2: value 123 | C2: value ABC | D2: date DD/MM/YYYY | E2: X | F2: X

Sheet Subasta_DATA
A1: Test Case No | B1: Field 1 | C1: Field 2 | D1: Field 3 | E1: Field 4 | F1: Field 5
A2: } | B2: value 123 | C2: value ABC | D2: date DD/MM/YYYY | E2: X | F2: X

Sheet OfertasSubasta_DATA
A1: Test Case No | B1: Field 1 | C1: Field 2 | D1: Field 3 | E1: Field 4 | F1: Field 5
A2: } | B2: value 123 | C2: value ABC | D2: date DD/MM/YYYY | E2: X | F2: X

Sheet AcciónCorporativa_DATA
A1: Test Case No | B1: Field 1 | C1: Field 2 | D1: Field 3 | E1: Field 4 | F1: Field 5
A2: } | B2: value 123 | C2: value ABC | D2: date DD/MM/YYYY | E2: X | F2: X

Sheet SistemaLiquidaciónEfectivo_DATA
A1: Test Case No | B1: Field 1 | C1: Field 2 | D1: Field 3 | E1: Field 4 | F1: Field 5
A2: } | B2: value 123 | C2: value ABC | D2: date DD/MM/YYYY | E2: X | F2: X

Sheet CatálogodeParámetros_DATA
A1: Test Case No | B1: Field 1 | C1: Field 2 | D1: Field 3 | E1: Field 4 | F1: Field 5
A2: } | B2: value 123 | C2: value ABC | D2: date DD/MM/YYYY | E2: X | F2: X

Sheet ParámetrosdeConfiguración_DATA
A1: Test Case No | B1: Field 1 | C1: Field 2 | D1: Field 3 | E1: Field 4 | F1: Field 5
A2: } | B2: value 123 | C2: value ABC | D2: date DD/MM/YYYY | E2: X | F2: X

Sheet CódigosdeOperación_DATA
A1: Test Case No | B1: Field 1 | C1: Field 2 | D1: Field 3 | E1: Field 4 | F1: Field 5
A2: } | B2: value 123 | C2: value ABC | D2: date DD/MM/YYYY | E2: X | F2: X

Sheet EntregaLibrePago_DATA
A1: Test Case No | B1: Field 1 | C1: Field 2 | D1: Field 3 | E1: Field 4 | F1: Field 5
A2: } | B2: value 123 | C2: value ABC | D2: date DD/MM/YYYY | E2: X | F2: X

Sheet CompraVentaEcP_DATA
A1: Test Case No | B1: Field 1 | C1: Field 2 | D1: Field 3 | E1: Field 4 | F1: Field 5
A2: } | B2: value 123 | C2: value ABC | D2: date DD/MM/YYYY | E2: X | F2: X

Sheet AcuerdosdeRecompra_DATA
A1: Test Case No | B1: Field 1 | C1: Field 2 | D1: Field 3 | E1: Field 4 | F1: Field 5
A2: } | B2: value 123 | C2: value ABC | D2: date DD/MM/YYYY | E2: X | F2: X

Sheet CambioFechaRepo_DATA
A1: Test Case No | B1: Field 1 | C1: Field 2 | D1: Field 3 | E1: Field 4 | F1: Field 5
A2: } | B2: value 123 | C2: value ABC | D2: date DD/MM/YYYY | E2: X | F2: X

Sheet SustituciónColateralRepo_DATA
A1: Test Case No | B1: Field 1 | C1: Field 2 | D1: Field 3 | E1: Field 4 | F1: Field 5
A2: } | B2: value 123 | C2: value ABC | D2: date DD/MM/YYYY | E2: X | F2: X

Sheet Pignoraciones_DATA
A1: Test Case No | B1: Field 1 | C1: Field 2 | D1: Field 3 | E1: Field 4 | F1: Field 5
A2: } | B2: value 123 | C2: value ABC | D2: date DD/MM/YYYY | E2: X | F2: X

Sheet SustituciónColateralPigno_DATA
A1: Test Case No | B1: Field 1 | C1: Field 2 | D1: Field 3 | E1: Field 4 | F1: Field 5
A2: } | B2: value 123 | C2: value ABC | D2: date DD/MM/YYYY | E2: X | F2: X

Sheet LiberaciónPignoración_DATA
A1: Test Case No | B1: Field 1 | C1: Field 2 | D1: Field 3 | E1: Field 4 | F1: Field 5
A2: } | B2: value 123 | C2: value ABC | D2: date DD/MM/YYYY | E2: X | F2: X

Sheet EjecuciónPignoración_DATA
A1: Test Case No | B1: Field 1 | C1: Field 2 | D1: Field 3 | E1: Field 4 | F1: Field 5
A2: } | B2: value 123 | C2: value ABC | D2: date DD/MM/YYYY | E2: X | F2: X

Sheet CambioFechaPignoración_DATA
A1: Test Case No | B1: Field 1 | C1: Field 2 | D1: Field 3 | E1: Field 4 | F1: Field 5
A2: } | B2: value 123 | C2: value ABC | D2: date DD/MM/YYYY | E2: X | F2: X

Sheet Emisión_DATA
A1: Test Case No | B1: Field 1 | C1: Field 2 | D1: Field 3 | E1: Field 4 | F1: Field 5
A2: } | B2: value 123 | C2: value ABC | D2: date DD/MM/YYYY | E2: X | F2: X

Sheet Redención_DATA
A1: Test Case No | B1: Field 1 | C1: Field 2 | D1: Field 3 | E1: Field 4 | F1: Field 5
A2: } | B2: value 123 | C2: value ABC | D2: date DD/MM/YYYY | E2: X | F2: X

Sheet Intercambio_DATA
A1: Test Case No | B1: Field 1 | C1: Field 2 | D1: Field 3 | E1: Field 4 | F1: Field 5
A2: } | B2: value 123 | C2: value ABC | D2: date DD/MM/YYYY | E2: X | F2: X

Sheet DesinversiónAnticipada_DATA
A1: Test Case No | B1: Field 1 | C1: Field 2 | D1: Field 3 | E1: Field 4 | F1: Field 5
A2: } | B2: value 123 | C2: value ABC | D2: date DD/MM/YYYY | E2: X | F2: X

Sheet RegistrodeEmbargos_DATA
A1: Test Case No | B1: Field 1 | C1: Field 2 | D1: Field 3 | E1: Field 4 | F1: Field 5
A2: } | B2: value 123 | C2: value ABC | D2: date DD/MM/YYYY | E2: X | F2: X

Sheet DescuponarConsolidar_DATA
A1: Test Case No | B1: Field 1 | C1: Field 2 | D1: Field 3 | E1: Field 4 | F1: Field 5
A2: } | B2: value 123 | C2: value ABC | D2: date DD/MM/YYYY | E2: X | F2: X

Sheet CSDExternoEntrada_DATA
A1: Test Case No | B1: Field 1 | C1: Field 2 | D1: Field 3 | E1: Field 4 | F1: Field 5
A2: } | B2: value 123 | C2: value ABC | D2: date DD/MM/YYYY | E2: X | F2: X

Sheet CSDExternoSalida_DATA
A1: Test Case No | B1: Field 1 | C1: Field 2 | D1: Field 3 | E1: Field 4 | F1: Field 5
A2: } | B2: value 123 | C2: value ABC | D2: date DD/MM/YYYY | E2: X | F2: X

Sheet MovimientoIntraposición_DATA
A1: Test Case No | B1: Field 1 | C1: Field 2 | D1: Field 3 | E1: Field 4 | F1: Field 5
A2: } | B2: value 123 | C2: value ABC | D2: date DD/MM/YYYY | E2: X | F2: X

Sheet RepoIntradíaBancoCentral_DATA
A1: Test Case No | B1: Field 1 | C1: Field 2 | D1: Field 3 | E1: Field 4 | F1: Field 5
A2: } | B2: value 123 | C2: value ABC | D2: date DD/MM/YYYY | E2: X | F2: X

Sheet CalificacióndeRiesgo_DATA
A1: Test Case No | B1: Field 1 | C1: Field 2 | D1: Field 3 | E1: Field 4 | F1: Field 5
A2: } | B2: value 123 | C2: value ABC | D2: date DD/MM/YYYY | E2: X | F2: X

Sheet CalificacióndelEmisor_DATA
A1: Test Case No | B1: Field 1 | C1: Field 2 | D1: Field 3 | E1: Field 4 | F1: Field 5
A2: } | B2: value 123 | C2: value ABC | D2: date DD/MM/YYYY | E2: X | F2: X

Sheet ElegibilidadContraparte_DATA
A1: Test Case No | B1: Field 1 | C1: Field 2 | D1: Field 3 | E1: Field 4 | F1: Field 5
A2: } | B2: value 123 | C2: value ABC | D2: date DD/MM/YYYY | E2: X | F2: X

Sheet ElegibilidadTítulos_DATA
A1: Test Case No | B1: Field 1 | C1: Field 2 | D1: Field 3 | E1: Field 4 | F1: Field 5
A2: } | B2: value 123 | C2: value ABC | D2: date DD/MM/YYYY | E2: X | F2: X

Sheet EsquemaImpuestos_DATA
A1: Test Case No | B1: Field 1 | C1: Field 2 | D1: Field 3 | E1: Field 4 | F1: Field 5
A2: } | B2: value 123 | C2: value ABC | D2: date DD/MM/YYYY | E2: X | F2: X

Sheet Calendario_DATA
A1: Test Case No | B1: Field 1 | C1: Field 2 | D1: Field 3 | E1: Field 4 | F1: Field 5
A2: } | B2: value 123 | C2: value ABC | D2: date DD/MM/YYYY | E2: X | F2: X

Sheet Horario_DATA
A1: Test Case No | B1: Field 1 | C1: Field 2 | D1: Field 3 | E1: Field 4 | F1: Field 5
A2: } | B2: value 123 | C2: value ABC | D2: date DD/MM/YYYY | E2: X | F2: X

Sheet TasadeCambio_DATA
A1: Test Case No | B1: Field 1 | C1: Field 2 | D1: Field 3 | E1: Field 4 | F1: Field 5
A2: } | B2: value 123 | C2: value ABC | D2: date DD/MM/YYYY | E2: X | F2: X

Sheet Alertas_DATA
A1: Test Case No | B1: Field 1 | C1: Field 2 | D1: Field 3 | E1: Field 4 | F1: Field 5
A2: } | B2: value 123 | C2: value ABC | D2: date DD/MM/YYYY | E2: X | F2: X

Sheet Facturación_DATA
A1: Test Case No | B1: Field 1 | C1: Field 2 | D1: Field 3 | E1: Field 4 | F1: Field 5
A2: } | B2: value 123 | C2: value ABC | D2: date DD/MM/YYYY | E2: X | F2: X
